<robot name = "robot">
    <link name="Body">
        <inertial>
            <origin xyz="0 0 1.0" rpy="0   0"/>
            <mass value="1" />
            <inertia ixx="100" ixy="0" ixz="0" iyy="100" iyz="0" izz="100" />
        </inertial>
        <visual>
            <origin xyz="0 0 1.0" rpy="0   0"/>
            <geometry>
                <box size="6 6 2" />
            </geometry>
            <material name="Cyan">
                <color rgba="0 1.0 1.0 1.0"/>
            </material>
        </visual>
        <collision>
            <origin xyz="0 0 1.0" rpy="0   0"/>
            <geometry>
                <box size="6 6 2" />
            </geometry>
        </collision>
    </link>
    <link name="Leg1">
        <inertial>
            <origin xyz="0 2.0 0.5" rpy="0 0 1.5707963267948966"/>
            <mass value="1" />
            <inertia ixx="100" ixy="0" ixz="0" iyy="100" iyz="0" izz="100" />
        </inertial>
        <visual>
            <origin xyz="0 2.0 0.5" rpy="0 0 1.5707963267948966"/>
            <geometry>
                <box size="4 1.5 1" />
            </geometry>
            <material name="Cyan">
                <color rgba="0 1.0 1.0 1.0"/>
            </material>
        </visual>
        <collision>
            <origin xyz="0 2.0 0.5" rpy="0 0 1.5707963267948966"/>
            <geometry>
                <box size="4 1.5 1" />
            </geometry>
        </collision>
    </link>
    <link name="Leg2">
        <inertial>
            <origin xyz="-2.0 0 0.5" rpy="0   0"/>
            <mass value="1" />
            <inertia ixx="100" ixy="0" ixz="0" iyy="100" iyz="0" izz="100" />
        </inertial>
        <visual>
            <origin xyz="-2.0 0 0.5" rpy="0   0"/>
            <geometry>
                <box size="4 1.5 1" />
            </geometry>
            <material name="Cyan">
                <color rgba="0 1.0 1.0 1.0"/>
            </material>
        </visual>
        <collision>
            <origin xyz="-2.0 0 0.5" rpy="0   0"/>
            <geometry>
                <box size="4 1.5 1" />
            </geometry>
        </collision>
    </link>
    <link name="Leg3">
        <inertial>
            <origin xyz="0 -2.0 0.5" rpy="0 0 1.5707963267948966"/>
            <mass value="1" />
            <inertia ixx="100" ixy="0" ixz="0" iyy="100" iyz="0" izz="100" />
        </inertial>
        <visual>
            <origin xyz="0 -2.0 0.5" rpy="0 0 1.5707963267948966"/>
            <geometry>
                <box size="4 1.5 1" />
            </geometry>
            <material name="Cyan">
                <color rgba="0 1.0 1.0 1.0"/>
            </material>
        </visual>
        <collision>
            <origin xyz="0 -2.0 0.5" rpy="0 0 1.5707963267948966"/>
            <geometry>
                <box size="4 1.5 1" />
            </geometry>
        </collision>
    </link>
    <link name="Leg4">
        <inertial>
            <origin xyz="2.0 0 0.5" rpy="0   0"/>
            <mass value="1" />
            <inertia ixx="100" ixy="0" ixz="0" iyy="100" iyz="0" izz="100" />
        </inertial>
        <visual>
            <origin xyz="2.0 0 0.5" rpy="0   0"/>
            <geometry>
                <box size="4 1.5 1" />
            </geometry>
            <material name="Cyan">
                <color rgba="0 1.0 1.0 1.0"/>
            </material>
        </visual>
        <collision>
            <origin xyz="2.0 0 0.5" rpy="0   0"/>
            <geometry>
                <box size="4 1.5 1" />
            </geometry>
        </collision>
    </link>
    <link name="wrist1">
        <inertial>
            <origin xyz="0 0 -0.75" rpy="0   0"/>
            <mass value="1" />
            <inertia ixx="100" ixy="0" ixz="0" iyy="100" iyz="0" izz="100" />
        </inertial>
        <visual>
            <origin xyz="0 0 -0.75" rpy="0   0"/>
            <geometry>
                <box size="1.5 1.5 1.5" />
            </geometry>
            <material name="Cyan">
                <color rgba="0 1.0 1.0 1.0"/>
            </material>
        </visual>
        <collision>
            <origin xyz="0 0 -0.75" rpy="0   0"/>
            <geometry>
                <box size="1.5 1.5 1.5" />
            </geometry>
        </collision>
    </link>
    <link name="wrist2">
        <inertial>
            <origin xyz="0 0 -0.75" rpy="0   0"/>
            <mass value="1" />
            <inertia ixx="100" ixy="0" ixz="0" iyy="100" iyz="0" izz="100" />
        </inertial>
        <visual>
            <origin xyz="0 0 -0.75" rpy="0   0"/>
            <geometry>
                <box size="1.5 1.5 1.5" />
            </geometry>
            <material name="Cyan">
                <color rgba="0 1.0 1.0 1.0"/>
            </material>
        </visual>
        <collision>
            <origin xyz="0 0 -0.75" rpy="0   0"/>
            <geometry>
                <box size="1.5 1.5 1.5" />
            </geometry>
        </collision>
    </link>
    <link name="wrist3">
        <inertial>
            <origin xyz="0 0 -0.75" rpy="0   0"/>
            <mass value="1" />
            <inertia ixx="100" ixy="0" ixz="0" iyy="100" iyz="0" izz="100" />
        </inertial>
        <visual>
            <origin xyz="0 0 -0.75" rpy="0   0"/>
            <geometry>
                <box size="1.5 1.5 1.5" />
            </geometry>
            <material name="Cyan">
                <color rgba="0 1.0 1.0 1.0"/>
            </material>
        </visual>
        <collision>
            <origin xyz="0 0 -0.75" rpy="0   0"/>
            <geometry>
                <box size="1.5 1.5 1.5" />
            </geometry>
        </collision>
    </link>
    <link name="wrist4">
        <inertial>
            <origin xyz="0 0 -0.75" rpy="0   0"/>
            <mass value="1" />
            <inertia ixx="100" ixy="0" ixz="0" iyy="100" iyz="0" izz="100" />
        </inertial>
        <visual>
            <origin xyz="0 0 -0.75" rpy="0   0"/>
            <geometry>
                <box size="1.5 1.5 1.5" />
            </geometry>
            <material name="Cyan">
                <color rgba="0 1.0 1.0 1.0"/>
            </material>
        </visual>
        <collision>
            <origin xyz="0 0 -0.75" rpy="0   0"/>
            <geometry>
                <box size="1.5 1.5 1.5" />
            </geometry>
        </collision>
    </link>
    <link name="wheel11">
        <inertial>
            <origin xyz="0.25 0 0" rpy="0 -1.5707963267948966 0"/>
            <mass value="1" />
            <inertia ixx="100" ixy="0" ixz="0" iyy="100" iyz="0" izz="100" />
        </inertial>
        <visual>
            <origin xyz="0.25 0 0" rpy="0 -1.5707963267948966 0"/>
            <geometry>
                <box size="1.5 1.5 0.5" />
            </geometry>
            <material name="Cyan">
                <color rgba="0 1.0 1.0 1.0"/>
            </material>
        </visual>
        <collision>
            <origin xyz="0.25 0 0" rpy="0 -1.5707963267948966 0"/>
            <geometry>
                <box size="1.5 1.5 0.5" />
            </geometry>
        </collision>
    </link>
    <link name="wheel12">
        <inertial>
            <origin xyz="-0.25 0 0" rpy="0 -1.5707963267948966 0"/>
            <mass value="1" />
            <inertia ixx="100" ixy="0" ixz="0" iyy="100" iyz="0" izz="100" />
        </inertial>
        <visual>
            <origin xyz="-0.25 0 0" rpy="0 -1.5707963267948966 0"/>
            <geometry>
                <box size="1.5 1.5 0.5" />
            </geometry>
            <material name="Cyan">
                <color rgba="0 1.0 1.0 1.0"/>
            </material>
        </visual>
        <collision>
            <origin xyz="-0.25 0 0" rpy="0 -1.5707963267948966 0"/>
            <geometry>
                <box size="1.5 1.5 0.5" />
            </geometry>
        </collision>
    </link>
    <link name="wheel21">
        <inertial>
            <origin xyz="0 0.25 0" rpy="-1.5707963267948966 0 0"/>
            <mass value="1" />
            <inertia ixx="100" ixy="0" ixz="0" iyy="100" iyz="0" izz="100" />
        </inertial>
        <visual>
            <origin xyz="0 0.25 0" rpy="-1.5707963267948966 0 0"/>
            <geometry>
                <box size="1.5 1.5 0.5" />
            </geometry>
            <material name="Cyan">
                <color rgba="0 1.0 1.0 1.0"/>
            </material>
        </visual>
        <collision>
            <origin xyz="0 0.25 0" rpy="-1.5707963267948966 0 0"/>
            <geometry>
                <box size="1.5 1.5 0.5" />
            </geometry>
        </collision>
    </link>
    <link name="wheel22">
        <inertial>
            <origin xyz="0 -0.25 0" rpy="-1.5707963267948966 0 0"/>
            <mass value="1" />
            <inertia ixx="100" ixy="0" ixz="0" iyy="100" iyz="0" izz="100" />
        </inertial>
        <visual>
            <origin xyz="0 -0.25 0" rpy="-1.5707963267948966 0 0"/>
            <geometry>
                <box size="1.5 1.5 0.5" />
            </geometry>
            <material name="Cyan">
                <color rgba="0 1.0 1.0 1.0"/>
            </material>
        </visual>
        <collision>
            <origin xyz="0 -0.25 0" rpy="-1.5707963267948966 0 0"/>
            <geometry>
                <box size="1.5 1.5 0.5" />
            </geometry>
        </collision>
    </link>
    <link name="wheel31">
        <inertial>
            <origin xyz="-0.25 0 0" rpy="0 -1.5707963267948966 0"/>
            <mass value="1" />
            <inertia ixx="100" ixy="0" ixz="0" iyy="100" iyz="0" izz="100" />
        </inertial>
        <visual>
            <origin xyz="-0.25 0 0" rpy="0 -1.5707963267948966 0"/>
            <geometry>
                <box size="1.5 1.5 0.5" />
            </geometry>
            <material name="Cyan">
                <color rgba="0 1.0 1.0 1.0"/>
            </material>
        </visual>
        <collision>
            <origin xyz="-0.25 0 0" rpy="0 -1.5707963267948966 0"/>
            <geometry>
                <box size="1.5 1.5 0.5" />
            </geometry>
        </collision>
    </link>
    <link name="wheel32">
        <inertial>
            <origin xyz="0.25 0 0" rpy="0 -1.5707963267948966 0"/>
            <mass value="1" />
            <inertia ixx="100" ixy="0" ixz="0" iyy="100" iyz="0" izz="100" />
        </inertial>
        <visual>
            <origin xyz="0.25 0 0" rpy="0 -1.5707963267948966 0"/>
            <geometry>
                <box size="1.5 1.5 0.5" />
            </geometry>
            <material name="Cyan">
                <color rgba="0 1.0 1.0 1.0"/>
            </material>
        </visual>
        <collision>
            <origin xyz="0.25 0 0" rpy="0 -1.5707963267948966 0"/>
            <geometry>
                <box size="1.5 1.5 0.5" />
            </geometry>
        </collision>
    </link>
    <link name="wheel41">
        <inertial>
            <origin xyz="0 -0.25 0" rpy="-1.5707963267948966 0 0"/>
            <mass value="1" />
            <inertia ixx="100" ixy="0" ixz="0" iyy="100" iyz="0" izz="100" />
        </inertial>
        <visual>
            <origin xyz="0 -0.25 0" rpy="-1.5707963267948966 0 0"/>
            <geometry>
                <box size="1.5 1.5 0.5" />
            </geometry>
            <material name="Cyan">
                <color rgba="0 1.0 1.0 1.0"/>
            </material>
        </visual>
        <collision>
            <origin xyz="0 -0.25 0" rpy="-1.5707963267948966 0 0"/>
            <geometry>
                <box size="1.5 1.5 0.5" />
            </geometry>
        </collision>
    </link>
    <link name="wheel42">
        <inertial>
            <origin xyz="0 0.25 0" rpy="-1.5707963267948966 0 0"/>
            <mass value="1" />
            <inertia ixx="100" ixy="0" ixz="0" iyy="100" iyz="0" izz="100" />
        </inertial>
        <visual>
            <origin xyz="0 0.25 0" rpy="-1.5707963267948966 0 0"/>
            <geometry>
                <box size="1.5 1.5 0.5" />
            </geometry>
            <material name="Cyan">
                <color rgba="0 1.0 1.0 1.0"/>
            </material>
        </visual>
        <collision>
            <origin xyz="0 0.25 0" rpy="-1.5707963267948966 0 0"/>
            <geometry>
                <box size="1.5 1.5 0.5" />
            </geometry>
        </collision>
    </link>
    <joint name="Body_Leg1" type="revolute">
       <parent link="Body"/>
       <child  link="Leg1"/>
       <origin rpy="0 0 0" xyz="0 3.0 1.0" />
       <axis xyz="-1 0 0"/>
       <limit effort="0.0" lower="-3.14159" upper="3.14159" velocity="0.0"/>
    </joint>
    <joint name="Body_Leg2" type="revolute">
       <parent link="Body"/>
       <child  link="Leg2"/>
       <origin rpy="0 0 0" xyz="-3.0 0 1.0" />
       <axis xyz="0 -1 0"/>
       <limit effort="0.0" lower="-3.14159" upper="3.14159" velocity="0.0"/>
    </joint>
    <joint name="Body_Leg3" type="revolute">
       <parent link="Body"/>
       <child  link="Leg3"/>
       <origin rpy="0 0 0" xyz="0 -3.0 1.0" />
       <axis xyz="1 0 0"/>
       <limit effort="0.0" lower="-3.14159" upper="3.14159" velocity="0.0"/>
    </joint>
    <joint name="Body_Leg4" type="revolute">
       <parent link="Body"/>
       <child  link="Leg4"/>
       <origin rpy="0 0 0" xyz="3.0 0 1.0" />
       <axis xyz="0 1 0"/>
       <limit effort="0.0" lower="-3.14159" upper="3.14159" velocity="0.0"/>
    </joint>
    <joint name="Leg1_wrist1" type="revolute">
       <parent link="Leg1"/>
       <child  link="wrist1"/>
       <origin rpy="0 0 0" xyz="0 3.25 0" />
       <axis xyz="0 0 1"/>
       <limit effort="0.0" lower="-3.14159" upper="3.14159" velocity="0.0"/>
    </joint>
    <joint name="Leg2_wrist2" type="revolute">
       <parent link="Leg2"/>
       <child  link="wrist2"/>
       <origin rpy="0 0 0" xyz="-3.25 0 0" />
       <axis xyz="0 0 1"/>
       <limit effort="0.0" lower="-3.14159" upper="3.14159" velocity="0.0"/>
    </joint>
    <joint name="Leg3_wrist3" type="revolute">
       <parent link="Leg3"/>
       <child  link="wrist3"/>
       <origin rpy="0 0 0" xyz="0 -3.25 0" />
       <axis xyz="0 0 1"/>
       <limit effort="0.0" lower="-3.14159" upper="3.14159" velocity="0.0"/>
    </joint>
    <joint name="Leg4_wrist4" type="revolute">
       <parent link="Leg4"/>
       <child  link="wrist4"/>
       <origin rpy="0 0 0" xyz="3.25 0 0" />
       <axis xyz="0 0 1"/>
       <limit effort="0.0" lower="-3.14159" upper="3.14159" velocity="0.0"/>
    </joint>
    <joint name="wrist1_wheel11" type="revolute">
       <parent link="wrist1"/>
       <child  link="wheel11"/>
       <origin rpy="0 0 0" xyz="0.75 0 -1.5" />
       <axis xyz="1 0 0"/>
       <limit effort="0.0" lower="-3.14159" upper="3.14159" velocity="0.0"/>
    </joint>
    <joint name="wrist1_wheel12" type="revolute">
       <parent link="wrist1"/>
       <child  link="wheel12"/>
       <origin rpy="0 0 0" xyz="-0.75 0 -1.5" />
       <axis xyz="-1 0 0"/>
       <limit effort="0.0" lower="-3.14159" upper="3.14159" velocity="0.0"/>
    </joint>
    <joint name="wrist2_wheel21" type="revolute">
       <parent link="wrist2"/>
       <child  link="wheel21"/>
       <origin rpy="0 0 0" xyz="0 0.75 -1.5" />
       <axis xyz="0 1 0"/>
       <limit effort="0.0" lower="-3.14159" upper="3.14159" velocity="0.0"/>
    </joint>
    <joint name="wrist2_wheel22" type="revolute">
       <parent link="wrist2"/>
       <child  link="wheel22"/>
       <origin rpy="0 0 0" xyz="0 -0.75 -1.5" />
       <axis xyz="0 -1 0"/>
       <limit effort="0.0" lower="-3.14159" upper="3.14159" velocity="0.0"/>
    </joint>
    <joint name="wrist3_wheel31" type="revolute">
       <parent link="wrist3"/>
       <child  link="wheel31"/>
       <origin rpy="0 0 0" xyz="-0.75 0 -1.5" />
       <axis xyz="-1 0 0"/>
       <limit effort="0.0" lower="-3.14159" upper="3.14159" velocity="0.0"/>
    </joint>
    <joint name="wrist3_wheel32" type="revolute">
       <parent link="wrist3"/>
       <child  link="wheel32"/>
       <origin rpy="0 0 0" xyz="0.75 0 -1.5" />
       <axis xyz="1 0 0"/>
       <limit effort="0.0" lower="-3.14159" upper="3.14159" velocity="0.0"/>
    </joint>
    <joint name="wrist4_wheel41" type="revolute">
       <parent link="wrist4"/>
       <child  link="wheel41"/>
       <origin rpy="0 0 0" xyz="0 -0.75 -1.5" />
       <axis xyz="0 -1 0"/>
       <limit effort="0.0" lower="-3.14159" upper="3.14159" velocity="0.0"/>
    </joint>
    <joint name="wrist4_wheel42" type="revolute">
       <parent link="wrist4"/>
       <child  link="wheel42"/>
       <origin rpy="0 0 0" xyz="0 0.75 -1.5" />
       <axis xyz="0 1 0"/>
       <limit effort="0.0" lower="-3.14159" upper="3.14159" velocity="0.0"/>
    </joint>
</robot>